Starting job 6551835
SLURM assigned me the node(s): gpu08
[I 12:48:44.129 NotebookApp] Serving notebooks from local directory: /nfs/homedirs/fuchsgru/MastersThesis
[I 12:48:44.129 NotebookApp] Jupyter Notebook 6.4.4 is running at:
[I 12:48:44.129 NotebookApp] http://gpu08.kdd.in.tum.de:8888/?token=0390ea4ff59739fd8c85232c41f67dd92e88236d2d8e108e
[I 12:48:44.129 NotebookApp]  or http://127.0.0.1:8888/?token=0390ea4ff59739fd8c85232c41f67dd92e88236d2d8e108e
[I 12:48:44.129 NotebookApp] Use Control-C to stop this server and shut down all kernels (twice to skip confirmation).
[C 12:48:44.173 NotebookApp] 
    
    To access the notebook, open this file in a browser:
        file:///nfs/homedirs/fuchsgru/.local/share/jupyter/runtime/nbserver-2430900-open.html
    Or copy and paste one of these URLs:
        http://gpu08.kdd.in.tum.de:8888/?token=0390ea4ff59739fd8c85232c41f67dd92e88236d2d8e108e
     or http://127.0.0.1:8888/?token=0390ea4ff59739fd8c85232c41f67dd92e88236d2d8e108e
[I 12:50:08.246 NotebookApp] 302 GET /?token=0390ea4ff59739fd8c85232c41f67dd92e88236d2d8e108e (172.24.64.22) 0.940000ms
/nfs/homedirs/fuchsgru/miniconda3/lib/python3.9/json/encoder.py:257: UserWarning: date_default is deprecated since jupyter_client 7.0.0. Use jupyter_client.jsonutil.json_default.
  return _iterencode(o, 0)
[I 12:50:21.596 NotebookApp] Creating new notebook in /evaluation_nbs
[W 12:50:24.208 NotebookApp] 404 GET /nbextensions/widgets/notebook/js/extension.js?v=20211104124843 (172.24.64.22) 20.040000ms referer=http://localhost:8889/notebooks/evaluation_nbs/Untitled.ipynb?kernel_name=python3
ERROR:asyncio:Exception in callback <TaskWakeupMethWrapper object at 0x7f78dbec3430>(<Future finis...igin\r\n\r\n'>)
handle: <Handle <TaskWakeupMethWrapper object at 0x7f78dbec3430>(<Future finis...igin\r\n\r\n'>)>
Traceback (most recent call last):
  File "/nfs/homedirs/fuchsgru/miniconda3/lib/python3.9/asyncio/events.py", line 80, in _run
    self._context.run(self._callback, *self._args)
RuntimeError: Cannot enter into task <Task pending name='Task-6' coro=<HTTP1ServerConnection._server_request_loop() running at /nfs/homedirs/fuchsgru/miniconda3/lib/python3.9/site-packages/tornado/http1connection.py:823> wait_for=<Future finished result=b'GET /kernel...rigin\r\n\r\n'> cb=[IOLoop.add_future.<locals>.<lambda>() at /nfs/homedirs/fuchsgru/miniconda3/lib/python3.9/site-packages/tornado/ioloop.py:688]> while another task <Task pending name='Task-2' coro=<KernelManager._async_start_kernel() running at /nfs/homedirs/fuchsgru/miniconda3/lib/python3.9/site-packages/jupyter_client/manager.py:336>> is being executed.
ERROR:asyncio:Exception in callback <TaskWakeupMethWrapper object at 0x7f78dbec3490>(<Future finis...igin\r\n\r\n'>)
handle: <Handle <TaskWakeupMethWrapper object at 0x7f78dbec3490>(<Future finis...igin\r\n\r\n'>)>
Traceback (most recent call last):
  File "/nfs/homedirs/fuchsgru/miniconda3/lib/python3.9/asyncio/events.py", line 80, in _run
    self._context.run(self._callback, *self._args)
RuntimeError: Cannot enter into task <Task pending name='Task-8' coro=<HTTP1ServerConnection._server_request_loop() running at /nfs/homedirs/fuchsgru/miniconda3/lib/python3.9/site-packages/tornado/http1connection.py:823> wait_for=<Future finished result=b'GET /api/co...rigin\r\n\r\n'> cb=[IOLoop.add_future.<locals>.<lambda>() at /nfs/homedirs/fuchsgru/miniconda3/lib/python3.9/site-packages/tornado/ioloop.py:688]> while another task <Task pending name='Task-2' coro=<KernelManager._async_start_kernel() running at /nfs/homedirs/fuchsgru/miniconda3/lib/python3.9/site-packages/jupyter_client/manager.py:337>> is being executed.
[I 12:50:24.343 NotebookApp] Kernel started: cea912a7-a839-4e1d-8e20-fbd5a74a4706, name: python3
/nfs/homedirs/fuchsgru/miniconda3/lib/python3.9/json/encoder.py:257: UserWarning: date_default is deprecated since jupyter_client 7.0.0. Use jupyter_client.jsonutil.json_default.
  return _iterencode(o, 0)
[W 12:50:39.049 NotebookApp] 404 GET /nbextensions/widgets/notebook/js/extension.js?v=20211104124843 (172.24.64.22) 1.630000ms referer=http://localhost:8889/notebooks/evaluation_nbs/week3_accuracy_vs_spectral_norm.ipynb
[I 12:50:39.292 NotebookApp] Kernel started: aeb0f546-8eec-4d94-822b-5134d4973696, name: python3
[I 12:52:24.396 NotebookApp] Saving file at /evaluation_nbs/week4_residual_accuracy.ipynb
[I 12:54:24.362 NotebookApp] Saving file at /evaluation_nbs/week4_residual_accuracy.ipynb
[I 12:56:24.370 NotebookApp] Saving file at /evaluation_nbs/week4_residual_accuracy.ipynb
[I 12:58:24.369 NotebookApp] Saving file at /evaluation_nbs/week4_residual_accuracy.ipynb
[I 13:00:24.374 NotebookApp] Saving file at /evaluation_nbs/week4_residual_accuracy.ipynb
[I 13:02:24.366 NotebookApp] Saving file at /evaluation_nbs/week4_residual_accuracy.ipynb
[I 13:04:24.372 NotebookApp] Saving file at /evaluation_nbs/week4_residual_accuracy.ipynb
[I 13:06:24.777 NotebookApp] Saving file at /evaluation_nbs/week4_residual_accuracy.ipynb
[I 13:08:24.382 NotebookApp] Saving file at /evaluation_nbs/week4_residual_accuracy.ipynb
[I 13:10:25.232 NotebookApp] Saving file at /evaluation_nbs/week4_residual_accuracy.ipynb
[I 13:12:25.865 NotebookApp] Saving file at /evaluation_nbs/week4_residual_accuracy.ipynb
[I 13:14:26.262 NotebookApp] Saving file at /evaluation_nbs/week4_residual_accuracy.ipynb
slurmstepd: error: *** JOB 6551835 ON gpu08 CANCELLED AT 2021-11-04T13:31:44 ***
